Workbook

Sheet Config_Equipamentos
A1: ID | B1: Área | C1: Equipamento | D1: Potência_kW | E1: Qtd_Peq | F1: Qtd_Med | G1: 00h | H1: 01h | I1: 02h | J1: 03h | K1: 04h | L1: 05h | M1: 06h | N1: 07h | O1: 08h | P1: 09h | Q1: 10h | R1: 11h | S1: 12h | T1: 13h | U1: 14h | V1: 15h | W1: 16h | X1: 17h | Y1: 18h | Z1: 19h | AA1: 20h | AB1: 21h | AC1: 22h | AD1: 23h
A2: ESC-01 | B2: Escritório | C2: Iluminação LED | D2: 0.1 | E2: 6 | F2: 10 | G2: 0 | H2: 0 | I2: 0 | J2: 0 | K2: 0 | L2: 0 | M2: 0 | N2: 1 | O2: 1 | P2: 1 | Q2: 1 | R2: 1 | S2: 1 | T2: 1 | U2: 1 | V2: 1 | W2: 1 | X2: 1 | Y2: 0 | Z2: 0 | AA2: 0 | AB2: 0 | AC2: 0 | AD2: 0
A3: ESC-02 | B3: Escritório | C3: Computador/Notebook | D3: 0.15 | E3: 2 | F3: 4 | G3: 0 | H3: 0 | I3: 0 | J3: 0 | K3: 0 | L3: 0 | M3: 0 | N3: 0 | O3: 1 | P3: 1 | Q3: 1 | R3: 1 | S3: 1 | T3: 1 | U3: 1 | V3: 1 | W3: 1 | X3: 0 | Y3: 0 | Z3: 0 | AA3: 0 | AB3: 0 | AC3: 0 | AD3: 0
A4: ESC-03 | B4: Escritório | C4: Impressora | D4: 0.3 | E4: 1 | F4: 1 | G4: 0 | H4: 0 | I4: 0 | J4: 0 | K4: 0 | L4: 0 | M4: 0 | N4: 0 | O4: 0.3 | P4: 0.3 | Q4: 0.3 | R4: 0.3 | S4: 0.3 | T4: 0.3 | U4: 0.3 | V4: 0.3 | W4: 0.3 | X4: 0 | Y4: 0 | Z4: 0 | AA4: 0 | AB4: 0 | AC4: 0 | AD4: 0
A5: ESC-04 | B5: Escritório | C5: Ar-condicionado | D5: 1.2 | E5: 1 | F5: 2 | G5: 0 | H5: 0 | I5: 0 | J5: 0 | K5: 0 | L5: 0 | M5: 0 | N5: 0 | O5: 0 | P5: 0.8 | Q5: 0.8 | R5: 0.8 | S5: 0.8 | T5: 0.8 | U5: 0.8 | V5: 0.8 | W5: 0.8 | X5: 0 | Y5: 0 | Z5: 0 | AA5: 0 | AB5: 0 | AC5: 0 | AD5: 0
A6: ESC-05 | B6: Escritório | C6: Roteador Wi-Fi | D6: 0.02 | E6: 1 | F6: 2 | G6: 1 | H6: 1 | I6: 1 | J6: 1 | K6: 1 | L6: 1 | M6: 1 | N6: 1 | O6: 1 | P6: 1 | Q6: 1 | R6: 1 | S6: 1 | T6: 1 | U6: 1 | V6: 1 | W6: 1 | X6: 1 | Y6: 1 | Z6: 1 | AA6: 1 | AB6: 1 | AC6: 1 | AD6: 1
A7: ESC-06 | B7: Escritório | C7: Carregadores | D7: 0.05 | E7: 2 | F7: 3 | G7: 0 | H7: 0 | I7: 0 | J7: 0 | K7: 0 | L7: 0 | M7: 0 | N7: 0 | O7: 0.5 | P7: 0.5 | Q7: 0.5 | R7: 0.5 | S7: 0.5 | T7: 0.5 | U7: 0.5 | V7: 0.5 | W7: 0.5 | X7: 0 | Y7: 0 | Z7: 0 | AA7: 0 | AB7: 0 | AC7: 0 | AD7: 0
A8: COZ-01 | B8: Cozinha | C8: Geladeira/Freezer | D8: 0.15 | E8: 1 | F8: 2 | G8: 0.4 | H8: 0.4 | I8: 0.4 | J8: 0.4 | K8: 0.4 | L8: 0.4 | M8: 0.4 | N8: 0.4 | O8: 0.4 | P8: 0.4 | Q8: 0.4 | R8: 0.4 | S8: 0.4 | T8: 0.4 | U8: 0.4 | V8: 0.4 | W8: 0.4 | X8: 0.4 | Y8: 0.4 | Z8: 0.4 | AA8: 0.4 | AB8: 0.4 | AC8: 0.4 | AD8: 0.4
A9: COZ-02 | B9: Cozinha | C9: Freezer horizontal | D9: 0.2 | E9: 1 | F9: 1 | G9: 0.35 | H9: 0.35 | I9: 0.35 | J9: 0.35 | K9: 0.35 | L9: 0.35 | M9: 0.35 | N9: 0.35 | O9: 0.35 | P9: 0.35 | Q9: 0.35 | R9: 0.35 | S9: 0.35 | T9: 0.35 | U9: 0.35 | V9: 0.35 | W9: 0.35 | X9: 0.35 | Y9: 0.35 | Z9: 0.35 | AA9: 0.35 | AB9: 0.35 | AC9: 0.35 | AD9: 0.35
A10: COZ-03 | B10: Cozinha | C10: Micro-ondas | D10: 1.2 | E10: 1 | F10: 1 | G10: 0 | H10: 0 | I10: 0 | J10: 0 | K10: 0 | L10: 0 | M10: 0.5 | N10: 0.5 | O10: 0 | P10: 0 | Q10: 0 | R10: 0 | S10: 0.8 | T10: 0.8 | U10: 0 | V10: 0 | W10: 0 | X10: 0.5 | Y10: 0.8 | Z10: 0.8 | AA10: 0 | AB10: 0 | AC10: 0 | AD10: 0
A11: COZ-04 | B11: Cozinha | C11: Cafeteira elétrica | D11: 0.8 | E11: 1 | F11: 1 | G11: 0 | H11: 0 | I11: 0 | J11: 0 | K11: 0 | L11: 0.5 | M11: 0.8 | N11: 0.8 | O11: 0.4 | P11: 0 | Q11: 0 | R11: 0 | S11: 0 | T11: 0 | U11: 0.4 | V11: 0.4 | W11: 0 | X11: 0 | Y11: 0 | Z11: 0 | AA11: 0 | AB11: 0 | AC11: 0 | AD11: 0
A12: COZ-05 | B12: Cozinha | C12: Iluminação LED | D12: 0.1 | E12: 4 | F12: 6 | G12: 0.3 | H12: 0.3 | I12: 0.3 | J12: 0.3 | K12: 0.3 | L12: 0.5 | M12: 0.8 | N12: 0.6 | O12: 0.4 | P12: 0.3 | Q12: 0.3 | R12: 0.5 | S12: 0.8 | T12: 0.5 | U12: 0.3 | V12: 0.3 | W12: 0.3 | X12: 0.5 | Y12: 0.8 | Z12: 0.6 | AA12: 0.4 | AB12: 0.3 | AC12: 0.3 | AD12: 0.3
A13: COZ-06 | B13: Cozinha | C13: Purificador de água | D13: 0.08 | E13: 1 | F13: 1 | G13: 0.3 | H13: 0.3 | I13: 0.3 | J13: 0.3 | K13: 0.3 | L13: 0.3 | M13: 0.3 | N13: 0.3 | O13: 0.3 | P13: 0.3 | Q13: 0.3 | R13: 0.3 | S13: 0.3 | T13: 0.3 | U13: 0.3 | V13: 0.3 | W13: 0.3 | X13: 0.3 | Y13: 0.3 | Z13: 0.3 | AA13: 0.3 | AB13: 0.3 | AC13: 0.3 | AD13: 0.3
... A17: QUA-04 | B17: Quarto | C17: Carregador celular | D17: 0.02 | E17: 3 | F17: 5 | G17: 0.8 | H17: 0.8 | I17: 0.8 | J17: 0.8 | K17: 0.5 | L17: 0.3 | M17: 0 | N17: 0 | O17: 0 | P17: 0 | Q17: 0 | R17: 0 | S17: 0 | T17: 0 | U17: 0 | V17: 0 | W17: 0 | X17: 0 | Y17: 0 | Z17: 0 | AA17: 0.3 | AB17: 0.5 | AC17: 0.8 | AD17: 0.9
A18: IRR-01 | B18: Irrigação/Lavoura | C18: Pivô central | D18: 4 | E18: 1 | F18: 2 | G18: 1 | H18: 1 | I18: 1 | J18: 1 | K18: 1 | L18: 0 | M18: 0 | N18: 0 | O18: 0 | P18: 0 | Q18: 0 | R18: 0 | S18: 0 | T18: 0 | U18: 0 | V18: 0 | W18: 0 | X18: 0 | Y18: 0 | Z18: 0 | AA18: 1 | AB18: 1 | AC18: 1 | AD18: 1 | AE18: Referência: Bomba pivo 3.68 kW planilha modelo_dados Darvin
A19: IRR-02 | B19: Irrigação/Lavoura | C19: Bomba auxiliar | D19: 22 | E19: 0 | F19: 1 | G19: 0.8 | H19: 0.8 | I19: 0 | J19: 0 | K19: 0 | L19: 0 | M19: 0 | N19: 0.8 | O19: 0.8 | P19: 0 | Q19: 0 | R19: 0 | S19: 0 | T19: 0 | U19: 0.8 | V19: 0.8 | W19: 0 | X19: 0 | Y19: 0 | Z19: 0 | AA19: 0.8 | AB19: 0.8 | AC19: 0 | AD19: 0 | AE19: Referência: Bomba captação 22.1 kW Planilha de modelo_dados Darvin
A20: IRR-03 | B20: Irrigação/Lavoura | C20: Secadora/Silo | D20: 2.4 | E20: 0 | F20: 1 | G20: 0.98625557 | H20: 0.98254086 | I20: 0.95839525 | J20: 0.98551263 | K20: 0.95319465 | L20: 0.99145617 | M20: 0.97956909 | N20: 0.96322437 | O20: 0.98774146 | P20: 0.98625557 | Q20: 0.97845468 | R20: 0.96582467 | S20: 0.96210996 | T20: 0.99071322 | U20: 1 | V20: 0.98402675 | W20: 0.9832838 | X20: 0.97771174 | Y20: 0.9910847 | Z20: 0.98922734 | AA20: 0.96508172 | AB20: 0.97399703 | AC20: 0.99294205 | AD20: 0.97622585
A21: IRR-04 | B21: Irrigação/Lavoura | C21: Quadro de automação | D21: 0.2 | E21: 1 | F21: 1 | G21: 1 | H21: 1 | I21: 1 | J21: 1 | K21: 1 | L21: 1 | M21: 1 | N21: 1 | O21: 1 | P21: 1 | Q21: 1 | R21: 1 | S21: 1 | T21: 1 | U21: 1 | V21: 1 | W21: 1 | X21: 1 | Y21: 1 | Z21: 1 | AA21: 1 | AB21: 1 | AC21: 1 | AD21: 1

Sheet Perfil_Area
A1: Perfil de Potência por Carga — DERIVADO dos Equipamentos
A2: Carga | B2: Tipo_Fazenda | C2: 00h_kW | D2: 01h_kW | E2: 02h_kW | F2: 03h_kW | G2: 04h_kW | H2: 05h_kW | I2: 06h_kW | J2: 07h_kW | K2: 08h_kW | L2: 09h_kW | M2: 10h_kW | N2: 11h_kW | O2: 12h_kW | P2: 13h_kW | Q2: 14h_kW | R2: 15h_kW | S2: 16h_kW | T2: 17h_kW | U2: 18h_kW | V2: 19h_kW | W2: 20h_kW | X2: 21h_kW | Y2: 22h_kW | Z2: 23h_kW | AA2: Total_kWh/dia
A3: Escritório | B3: Pequena | C3: =SUMPRODUCT((Config_Equipamentos!$B$2:$B$21="Escritório")*Config_Equipamentos!$D$2:$D$21*Config_Equipamentos!$E$2:$E$21*Config_Equipamentos!$G$2:$G$21) -> 0.02 | D3: =SUMPRODUCT((Config_Equipamentos!$B$2:$B$21="Escritório")*Config_Equipamentos!$D$2:$D$21*Config_Equipamentos!$E$2:$E$21*Config_Equipamentos!$H$2:$H$21) -> 0.02 | E3: =SUMPRODUCT((Config_Equipamentos!$B$2:$B$21="Escritório")*Config_Equipamentos!$D$2:$D$21*Config_Equipamentos!$E$2:$E$21*Config_Equipamentos!$I$2:$I$21) -> 0.02 | F3: =SUMPRODUCT((Config_Equipamentos!$B$2:$B$21="Escritório")*Config_Equipamentos!$D$2:$D$21*Config_Equipamentos!$E$2:$E$21*Config_Equipamentos!$J$2:$J$21) -> 0.02 | G3: =SUMPRODUCT((Config_Equipamentos!$B$2:$B$21="Escritório")*Config_Equipamentos!$D$2:$D$21*Config_Equipamentos!$E$2:$E$21*Config_Equipamentos!$K$2:$K$21) -> 0.02 | H3: =SUMPRODUCT((Config_Equipamentos!$B$2:$B$21="Escritório")*Config_Equipamentos!$D$2:$D$21*Config_Equipamentos!$E$2:$E$21*Config_Equipamentos!$L$2:$L$21) -> 0.02 | I3: =SUMPRODUCT((Config_Equipamentos!$B$2:$B$21="Escritório")*Config_Equipamentos!$D$2:$D$21*Config_Equipamentos!$E$2:$E$21*Config_Equipamentos!$M$2:$M$21) -> 0.02 | J3: =SUMPRODUCT((Config_Equipamentos!$B$2:$B$21="Escritório")*Config_Equipamentos!$D$2:$D$21*Config_Equipamentos!$E$2:$E$21*Config_Equipamentos!$N$2:$N$21) -> 0.62 | K3: =SUMPRODUCT((Config_Equipamentos!$B$2:$B$21="Escritório")*Config_Equipamentos!$D$2:$D$21*Config_Equipamentos!$E$2:$E$21*Config_Equipamentos!$O$2:$O$21) -> 1.06 | L3: =SUMPRODUCT((Config_Equipamentos!$B$2:$B$21="Escritório")*Config_Equipamentos!$D$2:$D$21*Config_Equipamentos!$E$2:$E$21*Config_Equipamentos!$P$2:$P$21) -> 2.02 | M3: =SUMPRODUCT((Config_Equipamentos!$B$2:$B$21="Escritório")*Config_Equipamentos!$D$2:$D$21*Config_Equipamentos!$E$2:$E$21*Config_Equipamentos!$Q$2:$Q$21) -> 2.02 | N3: =SUMPRODUCT((Config_Equipamentos!$B$2:$B$21="Escritório")*Config_Equipamentos!$D$2:$D$21*Config_Equipamentos!$E$2:$E$21*Config_Equipamentos!$R$2:$R$21) -> 2.02 | O3: =SUMPRODUCT((Config_Equipamentos!$B$2:$B$21="Escritório")*Config_Equipamentos!$D$2:$D$21*Config_Equipamentos!$E$2:$E$21*Config_Equipamentos!$S$2:$S$21) -> 2.02 | P3: =SUMPRODUCT((Config_Equipamentos!$B$2:$B$21="Escritório")*Config_Equipamentos!$D$2:$D$21*Config_Equipamentos!$E$2:$E$21*Config_Equipamentos!$T$2:$T$21) -> 2.02 | Q3: =SUMPRODUCT((Config_Equipamentos!$B$2:$B$21="Escritório")*Config_Equipamentos!$D$2:$D$21*Config_Equipamentos!$E$2:$E$21*Config_Equipamentos!$U$2:$U$21) -> 2.02 | R3: =SUMPRODUCT((Config_Equipamentos!$B$2:$B$21="Escritório")*Config_Equipamentos!$D$2:$D$21*Config_Equipamentos!$E$2:$E$21*Config_Equipamentos!$V$2:$V$21) -> 2.02 | S3: =SUMPRODUCT((Config_Equipamentos!$B$2:$B$21="Escritório")*Config_Equipamentos!$D$2:$D$21*Config_Equipamentos!$E$2:$E$21*Config_Equipamentos!$W$2:$W$21) -> 2.02 | T3: =SUMPRODUCT((Config_Equipamentos!$B$2:$B$21="Escritório")*Config_Equipamentos!$D$2:$D$21*Config_Equipamentos!$E$2:$E$21*Config_Equipamentos!$X$2:$X$21) -> 0.62 | U3: =SUMPRODUCT((Config_Equipamentos!$B$2:$B$21="Escritório")*Config_Equipamentos!$D$2:$D$21*Config_Equipamentos!$E$2:$E$21*Config_Equipamentos!$Y$2:$Y$21) -> 0.02 | V3: =SUMPRODUCT((Config_Equipamentos!$B$2:$B$21="Escritório")*Config_Equipamentos!$D$2:$D$21*Config_Equipamentos!$E$2:$E$21*Config_Equipamentos!$Z$2:$Z$21) -> 0.02 | W3: =SUMPRODUCT((Config_Equipamentos!$B$2:$B$21="Escritório")*Config_Equipamentos!$D$2:$D$21*Config_Equipamentos!$E$2:$E$21*Config_Equipamentos!$AA$2:$AA$21) -> 0.02 | X3: =SUMPRODUCT((Config_Equipamentos!$B$2:$B$21="Escritório")*Config_Equipamentos!$D$2:$D$21*Config_Equipamentos!$E$2:$E$21*Config_Equipamentos!$AB$2:$AB$21) -> 0.02 | Y3: =SUMPRODUCT((Config_Equipamentos!$B$2:$B$21="Escritório")*Config_Equipamentos!$D$2:$D$21*Config_Equipamentos!$E$2:$E$21*Config_Equipamentos!$AC$2:$AC$21) -> 0.02 | Z3: =SUMPRODUCT((Config_Equipamentos!$B$2:$B$21="Escritório")*Config_Equipamentos!$D$2:$D$21*Config_Equipamentos!$E$2:$E$21*Config_Equipamentos!$AD$2:$AD$21) -> 0.02 | AA3: =SUM(C3:Z3) -> 18.72
A4: Escritório | B4: Média | C4: =SUMPRODUCT((Config_Equipamentos!$B$2:$B$21="Escritório")*Config_Equipamentos!$D$2:$D$21*Config_Equipamentos!$F$2:$F$21*Config_Equipamentos!$G$2:$G$21) -> 0.04 | D4: =SUMPRODUCT((Config_Equipamentos!$B$2:$B$21="Escritório")*Config_Equipamentos!$D$2:$D$21*Config_Equipamentos!$F$2:$F$21*Config_Equipamentos!$H$2:$H$21) -> 0.04 | E4: =SUMPRODUCT((Config_Equipamentos!$B$2:$B$21="Escritório")*Config_Equipamentos!$D$2:$D$21*Config_Equipamentos!$F$2:$F$21*Config_Equipamentos!$I$2:$I$21) -> 0.04 | F4: =SUMPRODUCT((Config_Equipamentos!$B$2:$B$21="Escritório")*Config_Equipamentos!$D$2:$D$21*Config_Equipamentos!$F$2:$F$21*Config_Equipamentos!$J$2:$J$21) -> 0.04 | G4: =SUMPRODUCT((Config_Equipamentos!$B$2:$B$21="Escritório")*Config_Equipamentos!$D$2:$D$21*Config_Equipamentos!$F$2:$F$21*Config_Equipamentos!$K$2:$K$21) -> 0.04 | H4: =SUMPRODUCT((Config_Equipamentos!$B$2:$B$21="Escritório")*Config_Equipamentos!$D$2:$D$21*Config_Equipamentos!$F$2:$F$21*Config_Equipamentos!$L$2:$L$21) -> 0.04 | I4: =SUMPRODUCT((Config_Equipamentos!$B$2:$B$21="Escritório")*Config_Equipamentos!$D$2:$D$21*Config_Equipamentos!$F$2:$F$21*Config_Equipamentos!$M$2:$M$21) -> 0.04 | J4: =SUMPRODUCT((Config_Equipamentos!$B$2:$B$21="Escritório")*Config_Equipamentos!$D$2:$D$21*Config_Equipamentos!$F$2:$F$21*Config_Equipamentos!$N$2:$N$21) -> 1.04 | K4: =SUMPRODUCT((Config_Equipamentos!$B$2:$B$21="Escritório")*Config_Equipamentos!$D$2:$D$21*Config_Equipamentos!$F$2:$F$21*Config_Equipamentos!$O$2:$O$21) -> 1.805 | L4: =SUMPRODUCT((Config_Equipamentos!$B$2:$B$21="Escritório")*Config_Equipamentos!$D$2:$D$21*Config_Equipamentos!$F$2:$F$21*Config_Equipamentos!$P$2:$P$21) -> 3.725 | M4: =SUMPRODUCT((Config_Equipamentos!$B$2:$B$21="Escritório")*Config_Equipamentos!$D$2:$D$21*Config_Equipamentos!$F$2:$F$21*Config_Equipamentos!$Q$2:$Q$21) -> 3.725 | N4: =SUMPRODUCT((Config_Equipamentos!$B$2:$B$21="Escritório")*Config_Equipamentos!$D$2:$D$21*Config_Equipamentos!$F$2:$F$21*Config_Equipamentos!$R$2:$R$21) -> 3.725 | O4: =SUMPRODUCT((Config_Equipamentos!$B$2:$B$21="Escritório")*Config_Equipamentos!$D$2:$D$21*Config_Equipamentos!$F$2:$F$21*Config_Equipamentos!$S$2:$S$21) -> 3.725 | P4: =SUMPRODUCT((Config_Equipamentos!$B$2:$B$21="Escritório")*Config_Equipamentos!$D$2:$D$21*Config_Equipamentos!$F$2:$F$21*Config_Equipamentos!$T$2:$T$21) -> 3.725 | Q4: =SUMPRODUCT((Config_Equipamentos!$B$2:$B$21="Escritório")*Config_Equipamentos!$D$2:$D$21*Config_Equipamentos!$F$2:$F$21*Config_Equipamentos!$U$2:$U$21) -> 3.725 | R4: =SUMPRODUCT((Config_Equipamentos!$B$2:$B$21="Escritório")*Config_Equipamentos!$D$2:$D$21*Config_Equipamentos!$F$2:$F$21*Config_Equipamentos!$V$2:$V$21) -> 3.725 | S4: =SUMPRODUCT((Config_Equipamentos!$B$2:$B$21="Escritório")*Config_Equipamentos!$D$2:$D$21*Config_Equipamentos!$F$2:$F$21*Config_Equipamentos!$W$2:$W$21) -> 3.725 | T4: =SUMPRODUCT((Config_Equipamentos!$B$2:$B$21="Escritório")*Config_Equipamentos!$D$2:$D$21*Config_Equipamentos!$F$2:$F$21*Config_Equipamentos!$X$2:$X$21) -> 1.04 | U4: =SUMPRODUCT((Config_Equipamentos!$B$2:$B$21="Escritório")*Config_Equipamentos!$D$2:$D$21*Config_Equipamentos!$F$2:$F$21*Config_Equipamentos!$Y$2:$Y$21) -> 0.04 | V4: =SUMPRODUCT((Config_Equipamentos!$B$2:$B$21="Escritório")*Config_Equipamentos!$D$2:$D$21*Config_Equipamentos!$F$2:$F$21*Config_Equipamentos!$Z$2:$Z$21) -> 0.04 | W4: =SUMPRODUCT((Config_Equipamentos!$B$2:$B$21="Escritório")*Config_Equipamentos!$D$2:$D$21*Config_Equipamentos!$F$2:$F$21*Config_Equipamentos!$AA$2:$AA$21) -> 0.04 | X4: =SUMPRODUCT((Config_Equipamentos!$B$2:$B$21="Escritório")*Config_Equipamentos!$D$2:$D$21*Config_Equipamentos!$F$2:$F$21*Config_Equipamentos!$AB$2:$AB$21) -> 0.04 | Y4: =SUMPRODUCT((Config_Equipamentos!$B$2:$B$21="Escritório")*Config_Equipamentos!$D$2:$D$21*Config_Equipamentos!$F$2:$F$21*Config_Equipamentos!$AC$2:$AC$21) -> 0.04 | Z4: =SUMPRODUCT((Config_Equipamentos!$B$2:$B$21="Escritório")*Config_Equipamentos!$D$2:$D$21*Config_Equipamentos!$F$2:$F$21*Config_Equipamentos!$AD$2:$AD$21) -> 0.04 | AA4: =SUM(C4:Z4) -> 34.205
A5: Cozinha | B5: Pequena | C5: =SUMPRODUCT((Config_Equipamentos!$B$2:$B$21="Cozinha")*Config_Equipamentos!$D$2:$D$21*Config_Equipamentos!$E$2:$E$21*Config_Equipamentos!$G$2:$G$21) -> 0.274 | D5: =SUMPRODUCT((Config_Equipamentos!$B$2:$B$21="Cozinha")*Config_Equipamentos!$D$2:$D$21*Config_Equipamentos!$E$2:$E$21*Config_Equipamentos!$H$2:$H$21) -> 0.274 | E5: =SUMPRODUCT((Config_Equipamentos!$B$2:$B$21="Cozinha")*Config_Equipamentos!$D$2:$D$21*Config_Equipamentos!$E$2:$E$21*Config_Equipamentos!$I$2:$I$21) -> 0.274 | F5: =SUMPRODUCT((Config_Equipamentos!$B$2:$B$21="Cozinha")*Config_Equipamentos!$D$2:$D$21*Config_Equipamentos!$E$2:$E$21*Config_Equipamentos!$J$2:$J$21) -> 0.274 | G5: =SUMPRODUCT((Config_Equipamentos!$B$2:$B$21="Cozinha")*Config_Equipamentos!$D$2:$D$21*Config_Equipamentos!$E$2:$E$21*Config_Equipamentos!$K$2:$K$21) -> 0.274 | H5: =SUMPRODUCT((Config_Equipamentos!$B$2:$B$21="Cozinha")*Config_Equipamentos!$D$2:$D$21*Config_Equipamentos!$E$2:$E$21*Config_Equipamentos!$L$2:$L$21) -> 0.754 | I5: =SUMPRODUCT((Config_Equipamentos!$B$2:$B$21="Cozinha")*Config_Equipamentos!$D$2:$D$21*Config_Equipamentos!$E$2:$E$21*Config_Equipamentos!$M$2:$M$21) -> 1.714 | J5: =SUMPRODUCT((Config_Equipamentos!$B$2:$B$21="Cozinha")*Config_Equipamentos!$D$2:$D$21*Config_Equipamentos!$E$2:$E$21*Config_Equipamentos!$N$2:$N$21) -> 1.634 | K5: =SUMPRODUCT((Config_Equipamentos!$B$2:$B$21="Cozinha")*Config_Equipamentos!$D$2:$D$21*Config_Equipamentos!$E$2:$E$21*Config_Equipamentos!$O$2:$O$21) -> 0.634 | L5: =SUMPRODUCT((Config_Equipamentos!$B$2:$B$21="Cozinha")*Config_Equipamentos!$D$2:$D$21*Config_Equipamentos!$E$2:$E$21*Config_Equipamentos!$P$2:$P$21) -> 0.274 | M5: =SUMPRODUCT((Config_Equipamentos!$B$2:$B$21="Cozinha")*Config_Equipamentos!$D$2:$D$21*Config_Equipamentos!$E$2:$E$21*Config_Equipamentos!$Q$2:$Q$21) -> 0.274 | N5: =SUMPRODUCT((Config_Equipamentos!$B$2:$B$21="Cozinha")*Config_Equipamentos!$D$2:$D$21*Config_Equipamentos!$E$2:$E$21*Config_Equipamentos!$R$2:$R$21) -> 0.354 | O5: =SUMPRODUCT((Config_Equipamentos!$B$2:$B$21="Cozinha")*Config_Equipamentos!$D$2:$D$21*Config_Equipamentos!$E$2:$E$21*Config_Equipamentos!$S$2:$S$21) -> 1.434 | P5: =SUMPRODUCT((Config_Equipamentos!$B$2:$B$21="Cozinha")*Config_Equipamentos!$D$2:$D$21*Config_Equipamentos!$E$2:$E$21*Config_Equipamentos!$T$2:$T$21) -> 1.314 | Q5: =SUMPRODUCT((Config_Equipamentos!$B$2:$B$21="Cozinha")*Config_Equipamentos!$D$2:$D$21*Config_Equipamentos!$E$2:$E$21*Config_Equipamentos!$U$2:$U$21) -> 0.594 | R5: =SUMPRODUCT((Config_Equipamentos!$B$2:$B$21="Cozinha")*Config_Equipamentos!$D$2:$D$21*Config_Equipamentos!$E$2:$E$21*Config_Equipamentos!$V$2:$V$21) -> 0.594 | S5: =SUMPRODUCT((Config_Equipamentos!$B$2:$B$21="Cozinha")*Config_Equipamentos!$D$2:$D$21*Config_Equipamentos!$E$2:$E$21*Config_Equipamentos!$W$2:$W$21) -> 0.274 | T5: =SUMPRODUCT((Config_Equipamentos!$B$2:$B$21="Cozinha")*Config_Equipamentos!$D$2:$D$21*Config_Equipamentos!$E$2:$E$21*Config_Equipamentos!$X$2:$X$21) -> 0.954 | U5: =SUMPRODUCT((Config_Equipamentos!$B$2:$B$21="Cozinha")*Config_Equipamentos!$D$2:$D$21*Config_Equipamentos!$E$2:$E$21*Config_Equipamentos!$Y$2:$Y$21) -> 1.434 | V5: =SUMPRODUCT((Config_Equipamentos!$B$2:$B$21="Cozinha")*Config_Equipamentos!$D$2:$D$21*Config_Equipamentos!$E$2:$E$21*Config_Equipamentos!$Z$2:$Z$21) -> 1.354 | W5: =SUMPRODUCT((Config_Equipamentos!$B$2:$B$21="Cozinha")*Config_Equipamentos!$D$2:$D$21*Config_Equipamentos!$E$2:$E$21*Config_Equipamentos!$AA$2:$AA$21) -> 0.314 | X5: =SUMPRODUCT((Config_Equipamentos!$B$2:$B$21="Cozinha")*Config_Equipamentos!$D$2:$D$21*Config_Equipamentos!$E$2:$E$21*Config_Equipamentos!$AB$2:$AB$21) -> 0.274 | Y5: =SUMPRODUCT((Config_Equipamentos!$B$2:$B$21="Cozinha")*Config_Equipamentos!$D$2:$D$21*Config_Equipamentos!$E$2:$E$21*Config_Equipamentos!$AC$2:$AC$21) -> 0.274 | Z5: =SUMPRODUCT((Config_Equipamentos!$B$2:$B$21="Cozinha")*Config_Equipamentos!$D$2:$D$21*Config_Equipamentos!$E$2:$E$21*Config_Equipamentos!$AD$2:$AD$21) -> 0.274 | AA5: =SUM(C5:Z5) -> 16.096
A6: Cozinha | B6: Média | C6: =SUMPRODUCT((Config_Equipamentos!$B$2:$B$21="Cozinha")*Config_Equipamentos!$D$2:$D$21*Config_Equipamentos!$F$2:$F$21*Config_Equipamentos!$G$2:$G$21) -> 0.394 | D6: =SUMPRODUCT((Config_Equipamentos!$B$2:$B$21="Cozinha")*Config_Equipamentos!$D$2:$D$21*Config_Equipamentos!$F$2:$F$21*Config_Equipamentos!$H$2:$H$21) -> 0.394 | E6: =SUMPRODUCT((Config_Equipamentos!$B$2:$B$21="Cozinha")*Config_Equipamentos!$D$2:$D$21*Config_Equipamentos!$F$2:$F$21*Config_Equipamentos!$I$2:$I$21) -> 0.394 | F6: =SUMPRODUCT((Config_Equipamentos!$B$2:$B$21="Cozinha")*Config_Equipamentos!$D$2:$D$21*Config_Equipamentos!$F$2:$F$21*Config_Equipamentos!$J$2:$J$21) -> 0.394 | G6: =SUMPRODUCT((Config_Equipamentos!$B$2:$B$21="Cozinha")*Config_Equipamentos!$D$2:$D$21*Config_Equipamentos!$F$2:$F$21*Config_Equipamentos!$K$2:$K$21) -> 0.394 | H6: =SUMPRODUCT((Config_Equipamentos!$B$2:$B$21="Cozinha")*Config_Equipamentos!$D$2:$D$21*Config_Equipamentos!$F$2:$F$21*Config_Equipamentos!$L$2:$L$21) -> 0.914 | I6: =SUMPRODUCT((Config_Equipamentos!$B$2:$B$21="Cozinha")*Config_Equipamentos!$D$2:$D$21*Config_Equipamentos!$F$2:$F$21*Config_Equipamentos!$M$2:$M$21) -> 1.934 | J6: =SUMPRODUCT((Config_Equipamentos!$B$2:$B$21="Cozinha")*Config_Equipamentos!$D$2:$D$21*Config_Equipamentos!$F$2:$F$21*Config_Equipamentos!$N$2:$N$21) -> 1.814 | K6: =SUMPRODUCT((Config_Equipamentos!$B$2:$B$21="Cozinha")*Config_Equipamentos!$D$2:$D$21*Config_Equipamentos!$F$2:$F$21*Config_Equipamentos!$O$2:$O$21) -> 0.774 | L6: =SUMPRODUCT((Config_Equipamentos!$B$2:$B$21="Cozinha")*Config_Equipamentos!$D$2:$D$21*Config_Equipamentos!$F$2:$F$21*Config_Equipamentos!$P$2:$P$21) -> 0.394 | M6: =SUMPRODUCT((Config_Equipamentos!$B$2:$B$21="Cozinha")*Config_Equipamentos!$D$2:$D$21*Config_Equipamentos!$F$2:$F$21*Config_Equipamentos!$Q$2:$Q$21) -> 0.394 | N6: =SUMPRODUCT((Config_Equipamentos!$B$2:$B$21="Cozinha")*Config_Equipamentos!$D$2:$D$21*Config_Equipamentos!$F$2:$F$21*Config_Equipamentos!$R$2:$R$21) -> 0.514 | O6: =SUMPRODUCT((Config_Equipamentos!$B$2:$B$21="Cozinha")*Config_Equipamentos!$D$2:$D$21*Config_Equipamentos!$F$2:$F$21*Config_Equipamentos!$S$2:$S$21) -> 1.654 | P6: =SUMPRODUCT((Config_Equipamentos!$B$2:$B$21="Cozinha")*Config_Equipamentos!$D$2:$D$21*Config_Equipamentos!$F$2:$F$21*Config_Equipamentos!$T$2:$T$21) -> 1.474 | Q6: =SUMPRODUCT((Config_Equipamentos!$B$2:$B$21="Cozinha")*Config_Equipamentos!$D$2:$D$21*Config_Equipamentos!$F$2:$F$21*Config_Equipamentos!$U$2:$U$21) -> 0.714 | R6: =SUMPRODUCT((Config_Equipamentos!$B$2:$B$21="Cozinha")*Config_Equipamentos!$D$2:$D$21*Config_Equipamentos!$F$2:$F$21*Config_Equipamentos!$V$2:$V$21) -> 0.714 | S6: =SUMPRODUCT((Config_Equipamentos!$B$2:$B$21="Cozinha")*Config_Equipamentos!$D$2:$D$21*Config_Equipamentos!$F$2:$F$21*Config_Equipamentos!$W$2:$W$21) -> 0.394 | T6: =SUMPRODUCT((Config_Equipamentos!$B$2:$B$21="Cozinha")*Config_Equipamentos!$D$2:$D$21*Config_Equipamentos!$F$2:$F$21*Config_Equipamentos!$X$2:$X$21) -> 1.114 | U6: =SUMPRODUCT((Config_Equipamentos!$B$2:$B$21="Cozinha")*Config_Equipamentos!$D$2:$D$21*Config_Equipamentos!$F$2:$F$21*Config_Equipamentos!$Y$2:$Y$21) -> 1.654 | V6: =SUMPRODUCT((Config_Equipamentos!$B$2:$B$21="Cozinha")*Config_Equipamentos!$D$2:$D$21*Config_Equipamentos!$F$2:$F$21*Config_Equipamentos!$Z$2:$Z$21) -> 1.534 | W6: =SUMPRODUCT((Config_Equipamentos!$B$2:$B$21="Cozinha")*Config_Equipamentos!$D$2:$D$21*Config_Equipamentos!$F$2:$F$21*Config_Equipamentos!$AA$2:$AA$21) -> 0.454 | X6: =SUMPRODUCT((Config_Equipamentos!$B$2:$B$21="Cozinha")*Config_Equipamentos!$D$2:$D$21*Config_Equipamentos!$F$2:$F$21*Config_Equipamentos!$AB$2:$AB$21) -> 0.394 | Y6: =SUMPRODUCT((Config_Equipamentos!$B$2:$B$21="Cozinha")*Config_Equipamentos!$D$2:$D$21*Config_Equipamentos!$F$2:$F$21*Config_Equipamentos!$AC$2:$AC$21) -> 0.394 | Z6: =SUMPRODUCT((Config_Equipamentos!$B$2:$B$21="Cozinha")*Config_Equipamentos!$D$2:$D$21*Config_Equipamentos!$F$2:$F$21*Config_Equipamentos!$AD$2:$AD$21) -> 0.394 | AA6: =SUM(C6:Z6) -> 19.596
A7: Quarto | B7: Pequena | C7: =SUMPRODUCT((Config_Equipamentos!$B$2:$B$21="Quarto")*Config_Equipamentos!$D$2:$D$21*Config_Equipamentos!$E$2:$E$21*Config_Equipamentos!$G$2:$G$21) -> 0.176 | D7: =SUMPRODUCT((Config_Equipamentos!$B$2:$B$21="Quarto")*Config_Equipamentos!$D$2:$D$21*Config_Equipamentos!$E$2:$E$21*Config_Equipamentos!$H$2:$H$21) -> 0.176 | E7: =SUMPRODUCT((Config_Equipamentos!$B$2:$B$21="Quarto")*Config_Equipamentos!$D$2:$D$21*Config_Equipamentos!$E$2:$E$21*Config_Equipamentos!$I$2:$I$21) -> 0.176 | F7: =SUMPRODUCT((Config_Equipamentos!$B$2:$B$21="Quarto")*Config_Equipamentos!$D$2:$D$21*Config_Equipamentos!$E$2:$E$21*Config_Equipamentos!$J$2:$J$21) -> 0.176 | G7: =SUMPRODUCT((Config_Equipamentos!$B$2:$B$21="Quarto")*Config_Equipamentos!$D$2:$D$21*Config_Equipamentos!$E$2:$E$21*Config_Equipamentos!$K$2:$K$21) -> 0.158 | H7: =SUMPRODUCT((Config_Equipamentos!$B$2:$B$21="Quarto")*Config_Equipamentos!$D$2:$D$21*Config_Equipamentos!$E$2:$E$21*Config_Equipamentos!$L$2:$L$21) -> 0.114 | I7: =SUMPRODUCT((Config_Equipamentos!$B$2:$B$21="Quarto")*Config_Equipamentos!$D$2:$D$21*Config_Equipamentos!$E$2:$E$21*Config_Equipamentos!$M$2:$M$21) -> 0.048 | J7: =SUMPRODUCT((Config_Equipamentos!$B$2:$B$21="Quarto")*Config_Equipamentos!$D$2:$D$21*Config_Equipamentos!$E$2:$E$21*Config_Equipamentos!$N$2:$N$21) -> 0 | K7: =SUMPRODUCT((Config_Equipamentos!$B$2:$B$21="Quarto")*Config_Equipamentos!$D$2:$D$21*Config_Equipamentos!$E$2:$E$21*Config_Equipamentos!$O$2:$O$21) -> 0 | L7: =SUMPRODUCT((Config_Equipamentos!$B$2:$B$21="Quarto")*Config_Equipamentos!$D$2:$D$21*Config_Equipamentos!$E$2:$E$21*Config_Equipamentos!$P$2:$P$21) -> 0 | M7: =SUMPRODUCT((Config_Equipamentos!$B$2:$B$21="Quarto")*Config_Equipamentos!$D$2:$D$21*Config_Equipamentos!$E$2:$E$21*Config_Equipamentos!$Q$2:$Q$21) -> 0 | N7: =SUMPRODUCT((Config_Equipamentos!$B$2:$B$21="Quarto")*Config_Equipamentos!$D$2:$D$21*Config_Equipamentos!$E$2:$E$21*Config_Equipamentos!$R$2:$R$21) -> 0 | O7: =SUMPRODUCT((Config_Equipamentos!$B$2:$B$21="Quarto")*Config_Equipamentos!$D$2:$D$21*Config_Equipamentos!$E$2:$E$21*Config_Equipamentos!$S$2:$S$21) -> 0 | P7: =SUMPRODUCT((Config_Equipamentos!$B$2:$B$21="Quarto")*Config_Equipamentos!$D$2:$D$21*Config_Equipamentos!$E$2:$E$21*Config_Equipamentos!$T$2:$T$21) -> 0 | Q7: =SUMPRODUCT((Config_Equipamentos!$B$2:$B$21="Quarto")*Config_Equipamentos!$D$2:$D$21*Config_Equipamentos!$E$2:$E$21*Config_Equipamentos!$U$2:$U$21) -> 0 | R7: =SUMPRODUCT((Config_Equipamentos!$B$2:$B$21="Quarto")*Config_Equipamentos!$D$2:$D$21*Config_Equipamentos!$E$2:$E$21*Config_Equipamentos!$V$2:$V$21) -> 0 | S7: =SUMPRODUCT((Config_Equipamentos!$B$2:$B$21="Quarto")*Config_Equipamentos!$D$2:$D$21*Config_Equipamentos!$E$2:$E$21*Config_Equipamentos!$W$2:$W$21) -> 0 | T7: =SUMPRODUCT((Config_Equipamentos!$B$2:$B$21="Quarto")*Config_Equipamentos!$D$2:$D$21*Config_Equipamentos!$E$2:$E$21*Config_Equipamentos!$X$2:$X$21) -> 0 | U7: =SUMPRODUCT((Config_Equipamentos!$B$2:$B$21="Quarto")*Config_Equipamentos!$D$2:$D$21*Config_Equipamentos!$E$2:$E$21*Config_Equipamentos!$Y$2:$Y$21) -> 0.25 | V7: =SUMPRODUCT((Config_Equipamentos!$B$2:$B$21="Quarto")*Config_Equipamentos!$D$2:$D$21*Config_Equipamentos!$E$2:$E$21*Config_Equipamentos!$Z$2:$Z$21) -> 0.548 | W7: =SUMPRODUCT((Config_Equipamentos!$B$2:$B$21="Quarto")*Config_Equipamentos!$D$2:$D$21*Config_Equipamentos!$E$2:$E$21*Config_Equipamentos!$AA$2:$AA$21) -> 0.63 | X7: =SUMPRODUCT((Config_Equipamentos!$B$2:$B$21="Quarto")*Config_Equipamentos!$D$2:$D$21*Config_Equipamentos!$E$2:$E$21*Config_Equipamentos!$AB$2:$AB$21) -> 0.674 | Y7: =SUMPRODUCT((Config_Equipamentos!$B$2:$B$21="Quarto")*Config_Equipamentos!$D$2:$D$21*Config_Equipamentos!$E$2:$E$21*Config_Equipamentos!$AC$2:$AC$21) -> 0.608 | Z7: =SUMPRODUCT((Config_Equipamentos!$B$2:$B$21="Quarto")*Config_Equipamentos!$D$2:$D$21*Config_Equipamentos!$E$2:$E$21*Config_Equipamentos!$AD$2:$AD$21) -> 0.338 | AA7: =SUM(C7:Z7) -> 4.072
A8: Quarto | B8: Média | C8: =SUMPRODUCT((Config_Equipamentos!$B$2:$B$21="Quarto")*Config_Equipamentos!$D$2:$D$21*Config_Equipamentos!$F$2:$F$21*Config_Equipamentos!$G$2:$G$21) -> 0.336 | D8: =SUMPRODUCT((Config_Equipamentos!$B$2:$B$21="Quarto")*Config_Equipamentos!$D$2:$D$21*Config_Equipamentos!$F$2:$F$21*Config_Equipamentos!$H$2:$H$21) -> 0.336 | E8: =SUMPRODUCT((Config_Equipamentos!$B$2:$B$21="Quarto")*Config_Equipamentos!$D$2:$D$21*Config_Equipamentos!$F$2:$F$21*Config_Equipamentos!$I$2:$I$21) -> 0.336 | F8: =SUMPRODUCT((Config_Equipamentos!$B$2:$B$21="Quarto")*Config_Equipamentos!$D$2:$D$21*Config_Equipamentos!$F$2:$F$21*Config_Equipamentos!$J$2:$J$21) -> 0.336 | G8: =SUMPRODUCT((Config_Equipamentos!$B$2:$B$21="Quarto")*Config_Equipamentos!$D$2:$D$21*Config_Equipamentos!$F$2:$F$21*Config_Equipamentos!$K$2:$K$21) -> 0.306 | H8: =SUMPRODUCT((Config_Equipamentos!$B$2:$B$21="Quarto")*Config_Equipamentos!$D$2:$D$21*Config_Equipamentos!$F$2:$F$21*Config_Equipamentos!$L$2:$L$21) -> 0.222 | I8: =SUMPRODUCT((Config_Equipamentos!$B$2:$B$21="Quarto")*Config_Equipamentos!$D$2:$D$21*Config_Equipamentos!$F$2:$F$21*Config_Equipamentos!$M$2:$M$21) -> 0.096 | J8: =SUMPRODUCT((Config_Equipamentos!$B$2:$B$21="Quarto")*Config_Equipamentos!$D$2:$D$21*Config_Equipamentos!$F$2:$F$21*Config_Equipamentos!$N$2:$N$21) -> 0 | K8: =SUMPRODUCT((Config_Equipamentos!$B$2:$B$21="Quarto")*Config_Equipamentos!$D$2:$D$21*Config_Equipamentos!$F$2:$F$21*Config_Equipamentos!$O$2:$O$21) -> 0 | L8: =SUMPRODUCT((Config_Equipamentos!$B$2:$B$21="Quarto")*Config_Equipamentos!$D$2:$D$21*Config_Equipamentos!$F$2:$F$21*Config_Equipamentos!$P$2:$P$21) -> 0 | M8: =SUMPRODUCT((Config_Equipamentos!$B$2:$B$21="Quarto")*Config_Equipamentos!$D$2:$D$21*Config_Equipamentos!$F$2:$F$21*Config_Equipamentos!$Q$2:$Q$21) -> 0 | N8: =SUMPRODUCT((Config_Equipamentos!$B$2:$B$21="Quarto")*Config_Equipamentos!$D$2:$D$21*Config_Equipamentos!$F$2:$F$21*Config_Equipamentos!$R$2:$R$21) -> 0 | O8: =SUMPRODUCT((Config_Equipamentos!$B$2:$B$21="Quarto")*Config_Equipamentos!$D$2:$D$21*Config_Equipamentos!$F$2:$F$21*Config_Equipamentos!$S$2:$S$21) -> 0 | P8: =SUMPRODUCT((Config_Equipamentos!$B$2:$B$21="Quarto")*Config_Equipamentos!$D$2:$D$21*Config_Equipamentos!$F$2:$F$21*Config_Equipamentos!$T$2:$T$21) -> 0 | Q8: =SUMPRODUCT((Config_Equipamentos!$B$2:$B$21="Quarto")*Config_Equipamentos!$D$2:$D$21*Config_Equipamentos!$F$2:$F$21*Config_Equipamentos!$U$2:$U$21) -> 0 | R8: =SUMPRODUCT((Config_Equipamentos!$B$2:$B$21="Quarto")*Config_Equipamentos!$D$2:$D$21*Config_Equipamentos!$F$2:$F$21*Config_Equipamentos!$V$2:$V$21) -> 0 | S8: =SUMPRODUCT((Config_Equipamentos!$B$2:$B$21="Quarto")*Config_Equipamentos!$D$2:$D$21*Config_Equipamentos!$F$2:$F$21*Config_Equipamentos!$W$2:$W$21) -> 0 | T8: =SUMPRODUCT((Config_Equipamentos!$B$2:$B$21="Quarto")*Config_Equipamentos!$D$2:$D$21*Config_Equipamentos!$F$2:$F$21*Config_Equipamentos!$X$2:$X$21) -> 0 | U8: =SUMPRODUCT((Config_Equipamentos!$B$2:$B$21="Quarto")*Config_Equipamentos!$D$2:$D$21*Config_Equipamentos!$F$2:$F$21*Config_Equipamentos!$Y$2:$Y$21) -> 0.4 | V8: =SUMPRODUCT((Config_Equipamentos!$B$2:$B$21="Quarto")*Config_Equipamentos!$D$2:$D$21*Config_Equipamentos!$F$2:$F$21*Config_Equipamentos!$Z$2:$Z$21) -> 0.896 | W8: =SUMPRODUCT((Config_Equipamentos!$B$2:$B$21="Quarto")*Config_Equipamentos!$D$2:$D$21*Config_Equipamentos!$F$2:$F$21*Config_Equipamentos!$AA$2:$AA$21) -> 1.054 | X8: =SUMPRODUCT((Config_Equipamentos!$B$2:$B$21="Quarto")*Config_Equipamentos!$D$2:$D$21*Config_Equipamentos!$F$2:$F$21*Config_Equipamentos!$AB$2:$AB$21) -> 1.138 | Y8: =SUMPRODUCT((Config_Equipamentos!$B$2:$B$21="Quarto")*Config_Equipamentos!$D$2:$D$21*Config_Equipamentos!$F$2:$F$21*Config_Equipamentos!$AC$2:$AC$21) -> 1.04 | Z8: =SUMPRODUCT((Config_Equipamentos!$B$2:$B$21="Quarto")*Config_Equipamentos!$D$2:$D$21*Config_Equipamentos!$F$2:$F$21*Config_Equipamentos!$AD$2:$AD$21) -> 0.598 | AA8: =SUM(C8:Z8) -> 7.094
A9: Pivô | B9: Pequena | C9: =SUMPRODUCT((Config_Equipamentos!$B$2:$B$21="Irrigação/Lavoura")*(Config_Equipamentos!$C$2:$C$21="Pivô central")*Config_Equipamentos!$D$2:$D$21*Config_Equipamentos!$E$2:$E$21*Config_Equipamentos!$G$2:$G$21) -> 4 | D9: =SUMPRODUCT((Config_Equipamentos!$B$2:$B$21="Irrigação/Lavoura")*(Config_Equipamentos!$C$2:$C$21="Pivô central")*Config_Equipamentos!$D$2:$D$21*Config_Equipamentos!$E$2:$E$21*Config_Equipamentos!$H$2:$H$21) -> 4 | E9: =SUMPRODUCT((Config_Equipamentos!$B$2:$B$21="Irrigação/Lavoura")*(Config_Equipamentos!$C$2:$C$21="Pivô central")*Config_Equipamentos!$D$2:$D$21*Config_Equipamentos!$E$2:$E$21*Config_Equipamentos!$I$2:$I$21) -> 4 | F9: =SUMPRODUCT((Config_Equipamentos!$B$2:$B$21="Irrigação/Lavoura")*(Config_Equipamentos!$C$2:$C$21="Pivô central")*Config_Equipamentos!$D$2:$D$21*Config_Equipamentos!$E$2:$E$21*Config_Equipamentos!$J$2:$J$21) -> 4 | G9: =SUMPRODUCT((Config_Equipamentos!$B$2:$B$21="Irrigação/Lavoura")*(Config_Equipamentos!$C$2:$C$21="Pivô central")*Config_Equipamentos!$D$2:$D$21*Config_Equipamentos!$E$2:$E$21*Config_Equipamentos!$K$2:$K$21) -> 4 | H9: =SUMPRODUCT((Config_Equipamentos!$B$2:$B$21="Irrigação/Lavoura")*(Config_Equipamentos!$C$2:$C$21="Pivô central")*Config_Equipamentos!$D$2:$D$21*Config_Equipamentos!$E$2:$E$21*Config_Equipamentos!$L$2:$L$21) -> 0 | I9: =SUMPRODUCT((Config_Equipamentos!$B$2:$B$21="Irrigação/Lavoura")*(Config_Equipamentos!$C$2:$C$21="Pivô central")*Config_Equipamentos!$D$2:$D$21*Config_Equipamentos!$E$2:$E$21*Config_Equipamentos!$M$2:$M$21) -> 0 | J9: =SUMPRODUCT((Config_Equipamentos!$B$2:$B$21="Irrigação/Lavoura")*(Config_Equipamentos!$C$2:$C$21="Pivô central")*Config_Equipamentos!$D$2:$D$21*Config_Equipamentos!$E$2:$E$21*Config_Equipamentos!$N$2:$N$21) -> 0 | K9: =SUMPRODUCT((Config_Equipamentos!$B$2:$B$21="Irrigação/Lavoura")*(Config_Equipamentos!$C$2:$C$21="Pivô central")*Config_Equipamentos!$D$2:$D$21*Config_Equipamentos!$E$2:$E$21*Config_Equipamentos!$O$2:$O$21) -> 0 | L9: =SUMPRODUCT((Config_Equipamentos!$B$2:$B$21="Irrigação/Lavoura")*(Config_Equipamentos!$C$2:$C$21="Pivô central")*Config_Equipamentos!$D$2:$D$21*Config_Equipamentos!$E$2:$E$21*Config_Equipamentos!$P$2:$P$21) -> 0 | M9: =SUMPRODUCT((Config_Equipamentos!$B$2:$B$21="Irrigação/Lavoura")*(Config_Equipamentos!$C$2:$C$21="Pivô central")*Config_Equipamentos!$D$2:$D$21*Config_Equipamentos!$E$2:$E$21*Config_Equipamentos!$Q$2:$Q$21) -> 0 | N9: =SUMPRODUCT((Config_Equipamentos!$B$2:$B$21="Irrigação/Lavoura")*(Config_Equipamentos!$C$2:$C$21="Pivô central")*Config_Equipamentos!$D$2:$D$21*Config_Equipamentos!$E$2:$E$21*Config_Equipamentos!$R$2:$R$21) -> 0 | O9: =SUMPRODUCT((Config_Equipamentos!$B$2:$B$21="Irrigação/Lavoura")*(Config_Equipamentos!$C$2:$C$21="Pivô central")*Config_Equipamentos!$D$2:$D$21*Config_Equipamentos!$E$2:$E$21*Config_Equipamentos!$S$2:$S$21) -> 0 | P9: =SUMPRODUCT((Config_Equipamentos!$B$2:$B$21="Irrigação/Lavoura")*(Config_Equipamentos!$C$2:$C$21="Pivô central")*Config_Equipamentos!$D$2:$D$21*Config_Equipamentos!$E$2:$E$21*Config_Equipamentos!$T$2:$T$21) -> 0 | Q9: =SUMPRODUCT((Config_Equipamentos!$B$2:$B$21="Irrigação/Lavoura")*(Config_Equipamentos!$C$2:$C$21="Pivô central")*Config_Equipamentos!$D$2:$D$21*Config_Equipamentos!$E$2:$E$21*Config_Equipamentos!$U$2:$U$21) -> 0 | R9: =SUMPRODUCT((Config_Equipamentos!$B$2:$B$21="Irrigação/Lavoura")*(Config_Equipamentos!$C$2:$C$21="Pivô central")*Config_Equipamentos!$D$2:$D$21*Config_Equipamentos!$E$2:$E$21*Config_Equipamentos!$V$2:$V$21) -> 0 | S9: =SUMPRODUCT((Config_Equipamentos!$B$2:$B$21="Irrigação/Lavoura")*(Config_Equipamentos!$C$2:$C$21="Pivô central")*Config_Equipamentos!$D$2:$D$21*Config_Equipamentos!$E$2:$E$21*Config_Equipamentos!$W$2:$W$21) -> 0 | T9: =SUMPRODUCT((Config_Equipamentos!$B$2:$B$21="Irrigação/Lavoura")*(Config_Equipamentos!$C$2:$C$21="Pivô central")*Config_Equipamentos!$D$2:$D$21*Config_Equipamentos!$E$2:$E$21*Config_Equipamentos!$X$2:$X$21) -> 0 | U9: =SUMPRODUCT((Config_Equipamentos!$B$2:$B$21="Irrigação/Lavoura")*(Config_Equipamentos!$C$2:$C$21="Pivô central")*Config_Equipamentos!$D$2:$D$21*Config_Equipamentos!$E$2:$E$21*Config_Equipamentos!$Y$2:$Y$21) -> 0 | V9: =SUMPRODUCT((Config_Equipamentos!$B$2:$B$21="Irrigação/Lavoura")*(Config_Equipamentos!$C$2:$C$21="Pivô central")*Config_Equipamentos!$D$2:$D$21*Config_Equipamentos!$E$2:$E$21*Config_Equipamentos!$Z$2:$Z$21) -> 0 | W9: =SUMPRODUCT((Config_Equipamentos!$B$2:$B$21="Irrigação/Lavoura")*(Config_Equipamentos!$C$2:$C$21="Pivô central")*Config_Equipamentos!$D$2:$D$21*Config_Equipamentos!$E$2:$E$21*Config_Equipamentos!$AA$2:$AA$21) -> 4 | X9: =SUMPRODUCT((Config_Equipamentos!$B$2:$B$21="Irrigação/Lavoura")*(Config_Equipamentos!$C$2:$C$21="Pivô central")*Config_Equipamentos!$D$2:$D$21*Config_Equipamentos!$E$2:$E$21*Config_Equipamentos!$AB$2:$AB$21) -> 4 | Y9: =SUMPRODUCT((Config_Equipamentos!$B$2:$B$21="Irrigação/Lavoura")*(Config_Equipamentos!$C$2:$C$21="Pivô central")*Config_Equipamentos!$D$2:$D$21*Config_Equipamentos!$E$2:$E$21*Config_Equipamentos!$AC$2:$AC$21) -> 4 | Z9: =SUMPRODUCT((Config_Equipamentos!$B$2:$B$21="Irrigação/Lavoura")*(Config_Equipamentos!$C$2:$C$21="Pivô central")*Config_Equipamentos!$D$2:$D$21*Config_Equipamentos!$E$2:$E$21*Config_Equipamentos!$AD$2:$AD$21) -> 4 | AA9: =SUM(C9:Z9) -> 36
A10: Pivô | B10: Média | C10: =SUMPRODUCT((Config_Equipamentos!$B$2:$B$21="Irrigação/Lavoura")*(Config_Equipamentos!$C$2:$C$21="Pivô central")*Config_Equipamentos!$D$2:$D$21*Config_Equipamentos!$F$2:$F$21*Config_Equipamentos!$G$2:$G$21) -> 8 | D10: =SUMPRODUCT((Config_Equipamentos!$B$2:$B$21="Irrigação/Lavoura")*(Config_Equipamentos!$C$2:$C$21="Pivô central")*Config_Equipamentos!$D$2:$D$21*Config_Equipamentos!$F$2:$F$21*Config_Equipamentos!$H$2:$H$21) -> 8 | E10: =SUMPRODUCT((Config_Equipamentos!$B$2:$B$21="Irrigação/Lavoura")*(Config_Equipamentos!$C$2:$C$21="Pivô central")*Config_Equipamentos!$D$2:$D$21*Config_Equipamentos!$F$2:$F$21*Config_Equipamentos!$I$2:$I$21) -> 8 | F10: =SUMPRODUCT((Config_Equipamentos!$B$2:$B$21="Irrigação/Lavoura")*(Config_Equipamentos!$C$2:$C$21="Pivô central")*Config_Equipamentos!$D$2:$D$21*Config_Equipamentos!$F$2:$F$21*Config_Equipamentos!$J$2:$J$21) -> 8 | G10: =SUMPRODUCT((Config_Equipamentos!$B$2:$B$21="Irrigação/Lavoura")*(Config_Equipamentos!$C$2:$C$21="Pivô central")*Config_Equipamentos!$D$2:$D$21*Config_Equipamentos!$F$2:$F$21*Config_Equipamentos!$K$2:$K$21) -> 8 | H10: =SUMPRODUCT((Config_Equipamentos!$B$2:$B$21="Irrigação/Lavoura")*(Config_Equipamentos!$C$2:$C$21="Pivô central")*Config_Equipamentos!$D$2:$D$21*Config_Equipamentos!$F$2:$F$21*Config_Equipamentos!$L$2:$L$21) -> 0 | I10: =SUMPRODUCT((Config_Equipamentos!$B$2:$B$21="Irrigação/Lavoura")*(Config_Equipamentos!$C$2:$C$21="Pivô central")*Config_Equipamentos!$D$2:$D$21*Config_Equipamentos!$F$2:$F$21*Config_Equipamentos!$M$2:$M$21) -> 0 | J10: =SUMPRODUCT((Config_Equipamentos!$B$2:$B$21="Irrigação/Lavoura")*(Config_Equipamentos!$C$2:$C$21="Pivô central")*Config_Equipamentos!$D$2:$D$21*Config_Equipamentos!$F$2:$F$21*Config_Equipamentos!$N$2:$N$21) -> 0 | K10: =SUMPRODUCT((Config_Equipamentos!$B$2:$B$21="Irrigação/Lavoura")*(Config_Equipamentos!$C$2:$C$21="Pivô central")*Config_Equipamentos!$D$2:$D$21*Config_Equipamentos!$F$2:$F$21*Config_Equipamentos!$O$2:$O$21) -> 0 | L10: =SUMPRODUCT((Config_Equipamentos!$B$2:$B$21="Irrigação/Lavoura")*(Config_Equipamentos!$C$2:$C$21="Pivô central")*Config_Equipamentos!$D$2:$D$21*Config_Equipamentos!$F$2:$F$21*Config_Equipamentos!$P$2:$P$21) -> 0 | M10: =SUMPRODUCT((Config_Equipamentos!$B$2:$B$21="Irrigação/Lavoura")*(Config_Equipamentos!$C$2:$C$21="Pivô central")*Config_Equipamentos!$D$2:$D$21*Config_Equipamentos!$F$2:$F$21*Config_Equipamentos!$Q$2:$Q$21) -> 0 | N10: =SUMPRODUCT((Config_Equipamentos!$B$2:$B$21="Irrigação/Lavoura")*(Config_Equipamentos!$C$2:$C$21="Pivô central")*Config_Equipamentos!$D$2:$D$21*Config_Equipamentos!$F$2:$F$21*Config_Equipamentos!$R$2:$R$21) -> 0 | O10: =SUMPRODUCT((Config_Equipamentos!$B$2:$B$21="Irrigação/Lavoura")*(Config_Equipamentos!$C$2:$C$21="Pivô central")*Config_Equipamentos!$D$2:$D$21*Config_Equipamentos!$F$2:$F$21*Config_Equipamentos!$S$2:$S$21) -> 0 | P10: =SUMPRODUCT((Config_Equipamentos!$B$2:$B$21="Irrigação/Lavoura")*(Config_Equipamentos!$C$2:$C$21="Pivô central")*Config_Equipamentos!$D$2:$D$21*Config_Equipamentos!$F$2:$F$21*Config_Equipamentos!$T$2:$T$21) -> 0 | Q10: =SUMPRODUCT((Config_Equipamentos!$B$2:$B$21="Irrigação/Lavoura")*(Config_Equipamentos!$C$2:$C$21="Pivô central")*Config_Equipamentos!$D$2:$D$21*Config_Equipamentos!$F$2:$F$21*Config_Equipamentos!$U$2:$U$21) -> 0 | R10: =SUMPRODUCT((Config_Equipamentos!$B$2:$B$21="Irrigação/Lavoura")*(Config_Equipamentos!$C$2:$C$21="Pivô central")*Config_Equipamentos!$D$2:$D$21*Config_Equipamentos!$F$2:$F$21*Config_Equipamentos!$V$2:$V$21) -> 0 | S10: =SUMPRODUCT((Config_Equipamentos!$B$2:$B$21="Irrigação/Lavoura")*(Config_Equipamentos!$C$2:$C$21="Pivô central")*Config_Equipamentos!$D$2:$D$21*Config_Equipamentos!$F$2:$F$21*Config_Equipamentos!$W$2:$W$21) -> 0 | T10: =SUMPRODUCT((Config_Equipamentos!$B$2:$B$21="Irrigação/Lavoura")*(Config_Equipamentos!$C$2:$C$21="Pivô central")*Config_Equipamentos!$D$2:$D$21*Config_Equipamentos!$F$2:$F$21*Config_Equipamentos!$X$2:$X$21) -> 0 | U10: =SUMPRODUCT((Config_Equipamentos!$B$2:$B$21="Irrigação/Lavoura")*(Config_Equipamentos!$C$2:$C$21="Pivô central")*Config_Equipamentos!$D$2:$D$21*Config_Equipamentos!$F$2:$F$21*Config_Equipamentos!$Y$2:$Y$21) -> 0 | V10: =SUMPRODUCT((Config_Equipamentos!$B$2:$B$21="Irrigação/Lavoura")*(Config_Equipamentos!$C$2:$C$21="Pivô central")*Config_Equipamentos!$D$2:$D$21*Config_Equipamentos!$F$2:$F$21*Config_Equipamentos!$Z$2:$Z$21) -> 0 | W10: =SUMPRODUCT((Config_Equipamentos!$B$2:$B$21="Irrigação/Lavoura")*(Config_Equipamentos!$C$2:$C$21="Pivô central")*Config_Equipamentos!$D$2:$D$21*Config_Equipamentos!$F$2:$F$21*Config_Equipamentos!$AA$2:$AA$21) -> 8 | X10: =SUMPRODUCT((Config_Equipamentos!$B$2:$B$21="Irrigação/Lavoura")*(Config_Equipamentos!$C$2:$C$21="Pivô central")*Config_Equipamentos!$D$2:$D$21*Config_Equipamentos!$F$2:$F$21*Config_Equipamentos!$AB$2:$AB$21) -> 8 | Y10: =SUMPRODUCT((Config_Equipamentos!$B$2:$B$21="Irrigação/Lavoura")*(Config_Equipamentos!$C$2:$C$21="Pivô central")*Config_Equipamentos!$D$2:$D$21*Config_Equipamentos!$F$2:$F$21*Config_Equipamentos!$AC$2:$AC$21) -> 8 | Z10: =SUMPRODUCT((Config_Equipamentos!$B$2:$B$21="Irrigação/Lavoura")*(Config_Equipamentos!$C$2:$C$21="Pivô central")*Config_Equipamentos!$D$2:$D$21*Config_Equipamentos!$F$2:$F$21*Config_Equipamentos!$AD$2:$AD$21) -> 8 | AA10: =SUM(C10:Z10) -> 72
A11: Bomba_Aux | B11: Pequena | C11: =SUMPRODUCT((Config_Equipamentos!$B$2:$B$21="Irrigação/Lavoura")*(Config_Equipamentos!$C$2:$C$21="Bomba auxiliar")*Config_Equipamentos!$D$2:$D$21*Config_Equipamentos!$E$2:$E$21*Config_Equipamentos!$G$2:$G$21) -> 0 | D11: =SUMPRODUCT((Config_Equipamentos!$B$2:$B$21="Irrigação/Lavoura")*(Config_Equipamentos!$C$2:$C$21="Bomba auxiliar")*Config_Equipamentos!$D$2:$D$21*Config_Equipamentos!$E$2:$E$21*Config_Equipamentos!$H$2:$H$21) -> 0 | E11: =SUMPRODUCT((Config_Equipamentos!$B$2:$B$21="Irrigação/Lavoura")*(Config_Equipamentos!$C$2:$C$21="Bomba auxiliar")*Config_Equipamentos!$D$2:$D$21*Config_Equipamentos!$E$2:$E$21*Config_Equipamentos!$I$2:$I$21) -> 0 | F11: =SUMPRODUCT((Config_Equipamentos!$B$2:$B$21="Irrigação/Lavoura")*(Config_Equipamentos!$C$2:$C$21="Bomba auxiliar")*Config_Equipamentos!$D$2:$D$21*Config_Equipamentos!$E$2:$E$21*Config_Equipamentos!$J$2:$J$21) -> 0 | G11: =SUMPRODUCT((Config_Equipamentos!$B$2:$B$21="Irrigação/Lavoura")*(Config_Equipamentos!$C$2:$C$21="Bomba auxiliar")*Config_Equipamentos!$D$2:$D$21*Config_Equipamentos!$E$2:$E$21*Config_Equipamentos!$K$2:$K$21) -> 0 | H11: =SUMPRODUCT((Config_Equipamentos!$B$2:$B$21="Irrigação/Lavoura")*(Config_Equipamentos!$C$2:$C$21="Bomba auxiliar")*Config_Equipamentos!$D$2:$D$21*Config_Equipamentos!$E$2:$E$21*Config_Equipamentos!$L$2:$L$21) -> 0 | I11: =SUMPRODUCT((Config_Equipamentos!$B$2:$B$21="Irrigação/Lavoura")*(Config_Equipamentos!$C$2:$C$21="Bomba auxiliar")*Config_Equipamentos!$D$2:$D$21*Config_Equipamentos!$E$2:$E$21*Config_Equipamentos!$M$2:$M$21) -> 0 | J11: =SUMPRODUCT((Config_Equipamentos!$B$2:$B$21="Irrigação/Lavoura")*(Config_Equipamentos!$C$2:$C$21="Bomba auxiliar")*Config_Equipamentos!$D$2:$D$21*Config_Equipamentos!$E$2:$E$21*Config_Equipamentos!$N$2:$N$21) -> 0 | K11: =SUMPRODUCT((Config_Equipamentos!$B$2:$B$21="Irrigação/Lavoura")*(Config_Equipamentos!$C$2:$C$21="Bomba auxiliar")*Config_Equipamentos!$D$2:$D$21*Config_Equipamentos!$E$2:$E$21*Config_Equipamentos!$O$2:$O$21) -> 0 | L11: =SUMPRODUCT((Config_Equipamentos!$B$2:$B$21="Irrigação/Lavoura")*(Config_Equipamentos!$C$2:$C$21="Bomba auxiliar")*Config_Equipamentos!$D$2:$D$21*Config_Equipamentos!$E$2:$E$21*Config_Equipamentos!$P$2:$P$21) -> 0 | M11: =SUMPRODUCT((Config_Equipamentos!$B$2:$B$21="Irrigação/Lavoura")*(Config_Equipamentos!$C$2:$C$21="Bomba auxiliar")*Config_Equipamentos!$D$2:$D$21*Config_Equipamentos!$E$2:$E$21*Config_Equipamentos!$Q$2:$Q$21) -> 0 | N11: =SUMPRODUCT((Config_Equipamentos!$B$2:$B$21="Irrigação/Lavoura")*(Config_Equipamentos!$C$2:$C$21="Bomba auxiliar")*Config_Equipamentos!$D$2:$D$21*Config_Equipamentos!$E$2:$E$21*Config_Equipamentos!$R$2:$R$21) -> 0 | O11: =SUMPRODUCT((Config_Equipamentos!$B$2:$B$21="Irrigação/Lavoura")*(Config_Equipamentos!$C$2:$C$21="Bomba auxiliar")*Config_Equipamentos!$D$2:$D$21*Config_Equipamentos!$E$2:$E$21*Config_Equipamentos!$S$2:$S$21) -> 0 | P11: =SUMPRODUCT((Config_Equipamentos!$B$2:$B$21="Irrigação/Lavoura")*(Config_Equipamentos!$C$2:$C$21="Bomba auxiliar")*Config_Equipamentos!$D$2:$D$21*Config_Equipamentos!$E$2:$E$21*Config_Equipamentos!$T$2:$T$21) -> 0 | Q11: =SUMPRODUCT((Config_Equipamentos!$B$2:$B$21="Irrigação/Lavoura")*(Config_Equipamentos!$C$2:$C$21="Bomba auxiliar")*Config_Equipamentos!$D$2:$D$21*Config_Equipamentos!$E$2:$E$21*Config_Equipamentos!$U$2:$U$21) -> 0 | R11: =SUMPRODUCT((Config_Equipamentos!$B$2:$B$21="Irrigação/Lavoura")*(Config_Equipamentos!$C$2:$C$21="Bomba auxiliar")*Config_Equipamentos!$D$2:$D$21*Config_Equipamentos!$E$2:$E$21*Config_Equipamentos!$V$2:$V$21) -> 0 | S11: =SUMPRODUCT((Config_Equipamentos!$B$2:$B$21="Irrigação/Lavoura")*(Config_Equipamentos!$C$2:$C$21="Bomba auxiliar")*Config_Equipamentos!$D$2:$D$21*Config_Equipamentos!$E$2:$E$21*Config_Equipamentos!$W$2:$W$21) -> 0 | T11: =SUMPRODUCT((Config_Equipamentos!$B$2:$B$21="Irrigação/Lavoura")*(Config_Equipamentos!$C$2:$C$21="Bomba auxiliar")*Config_Equipamentos!$D$2:$D$21*Config_Equipamentos!$E$2:$E$21*Config_Equipamentos!$X$2:$X$21) -> 0 | U11: =SUMPRODUCT((Config_Equipamentos!$B$2:$B$21="Irrigação/Lavoura")*(Config_Equipamentos!$C$2:$C$21="Bomba auxiliar")*Config_Equipamentos!$D$2:$D$21*Config_Equipamentos!$E$2:$E$21*Config_Equipamentos!$Y$2:$Y$21) -> 0 | V11: =SUMPRODUCT((Config_Equipamentos!$B$2:$B$21="Irrigação/Lavoura")*(Config_Equipamentos!$C$2:$C$21="Bomba auxiliar")*Config_Equipamentos!$D$2:$D$21*Config_Equipamentos!$E$2:$E$21*Config_Equipamentos!$Z$2:$Z$21) -> 0 | W11: =SUMPRODUCT((Config_Equipamentos!$B$2:$B$21="Irrigação/Lavoura")*(Config_Equipamentos!$C$2:$C$21="Bomba auxiliar")*Config_Equipamentos!$D$2:$D$21*Config_Equipamentos!$E$2:$E$21*Config_Equipamentos!$AA$2:$AA$21) -> 0 | X11: =SUMPRODUCT((Config_Equipamentos!$B$2:$B$21="Irrigação/Lavoura")*(Config_Equipamentos!$C$2:$C$21="Bomba auxiliar")*Config_Equipamentos!$D$2:$D$21*Config_Equipamentos!$E$2:$E$21*Config_Equipamentos!$AB$2:$AB$21) -> 0 | Y11: =SUMPRODUCT((Config_Equipamentos!$B$2:$B$21="Irrigação/Lavoura")*(Config_Equipamentos!$C$2:$C$21="Bomba auxiliar")*Config_Equipamentos!$D$2:$D$21*Config_Equipamentos!$E$2:$E$21*Config_Equipamentos!$AC$2:$AC$21) -> 0 | Z11: =SUMPRODUCT((Config_Equipamentos!$B$2:$B$21="Irrigação/Lavoura")*(Config_Equipamentos!$C$2:$C$21="Bomba auxiliar")*Config_Equipamentos!$D$2:$D$21*Config_Equipamentos!$E$2:$E$21*Config_Equipamentos!$AD$2:$AD$21) -> 0 | AA11: =SUM(C11:Z11) -> 0
A12: Bomba_Aux | B12: Média | C12: =SUMPRODUCT((Config_Equipamentos!$B$2:$B$21="Irrigação/Lavoura")*(Config_Equipamentos!$C$2:$C$21="Bomba auxiliar")*Config_Equipamentos!$D$2:$D$21*Config_Equipamentos!$F$2:$F$21*Config_Equipamentos!$G$2:$G$21) -> 17.6 | D12: =SUMPRODUCT((Config_Equipamentos!$B$2:$B$21="Irrigação/Lavoura")*(Config_Equipamentos!$C$2:$C$21="Bomba auxiliar")*Config_Equipamentos!$D$2:$D$21*Config_Equipamentos!$F$2:$F$21*Config_Equipamentos!$H$2:$H$21) -> 17.6 | E12: =SUMPRODUCT((Config_Equipamentos!$B$2:$B$21="Irrigação/Lavoura")*(Config_Equipamentos!$C$2:$C$21="Bomba auxiliar")*Config_Equipamentos!$D$2:$D$21*Config_Equipamentos!$F$2:$F$21*Config_Equipamentos!$I$2:$I$21) -> 0 | F12: =SUMPRODUCT((Config_Equipamentos!$B$2:$B$21="Irrigação/Lavoura")*(Config_Equipamentos!$C$2:$C$21="Bomba auxiliar")*Config_Equipamentos!$D$2:$D$21*Config_Equipamentos!$F$2:$F$21*Config_Equipamentos!$J$2:$J$21) -> 0 | G12: =SUMPRODUCT((Config_Equipamentos!$B$2:$B$21="Irrigação/Lavoura")*(Config_Equipamentos!$C$2:$C$21="Bomba auxiliar")*Config_Equipamentos!$D$2:$D$21*Config_Equipamentos!$F$2:$F$21*Config_Equipamentos!$K$2:$K$21) -> 0 | H12: =SUMPRODUCT((Config_Equipamentos!$B$2:$B$21="Irrigação/Lavoura")*(Config_Equipamentos!$C$2:$C$21="Bomba auxiliar")*Config_Equipamentos!$D$2:$D$21*Config_Equipamentos!$F$2:$F$21*Config_Equipamentos!$L$2:$L$21) -> 0 | I12: =SUMPRODUCT((Config_Equipamentos!$B$2:$B$21="Irrigação/Lavoura")*(Config_Equipamentos!$C$2:$C$21="Bomba auxiliar")*Config_Equipamentos!$D$2:$D$21*Config_Equipamentos!$F$2:$F$21*Config_Equipamentos!$M$2:$M$21) -> 0 | J12: =SUMPRODUCT((Config_Equipamentos!$B$2:$B$21="Irrigação/Lavoura")*(Config_Equipamentos!$C$2:$C$21="Bomba auxiliar")*Config_Equipamentos!$D$2:$D$21*Config_Equipamentos!$F$2:$F$21*Config_Equipamentos!$N$2:$N$21) -> 17.6 | K12: =SUMPRODUCT((Config_Equipamentos!$B$2:$B$21="Irrigação/Lavoura")*(Config_Equipamentos!$C$2:$C$21="Bomba auxiliar")*Config_Equipamentos!$D$2:$D$21*Config_Equipamentos!$F$2:$F$21*Config_Equipamentos!$O$2:$O$21) -> 17.6 | L12: =SUMPRODUCT((Config_Equipamentos!$B$2:$B$21="Irrigação/Lavoura")*(Config_Equipamentos!$C$2:$C$21="Bomba auxiliar")*Config_Equipamentos!$D$2:$D$21*Config_Equipamentos!$F$2:$F$21*Config_Equipamentos!$P$2:$P$21) -> 0 | M12: =SUMPRODUCT((Config_Equipamentos!$B$2:$B$21="Irrigação/Lavoura")*(Config_Equipamentos!$C$2:$C$21="Bomba auxiliar")*Config_Equipamentos!$D$2:$D$21*Config_Equipamentos!$F$2:$F$21*Config_Equipamentos!$Q$2:$Q$21) -> 0 | N12: =SUMPRODUCT((Config_Equipamentos!$B$2:$B$21="Irrigação/Lavoura")*(Config_Equipamentos!$C$2:$C$21="Bomba auxiliar")*Config_Equipamentos!$D$2:$D$21*Config_Equipamentos!$F$2:$F$21*Config_Equipamentos!$R$2:$R$21) -> 0 | O12: =SUMPRODUCT((Config_Equipamentos!$B$2:$B$21="Irrigação/Lavoura")*(Config_Equipamentos!$C$2:$C$21="Bomba auxiliar")*Config_Equipamentos!$D$2:$D$21*Config_Equipamentos!$F$2:$F$21*Config_Equipamentos!$S$2:$S$21) -> 0 | P12: =SUMPRODUCT((Config_Equipamentos!$B$2:$B$21="Irrigação/Lavoura")*(Config_Equipamentos!$C$2:$C$21="Bomba auxiliar")*Config_Equipamentos!$D$2:$D$21*Config_Equipamentos!$F$2:$F$21*Config_Equipamentos!$T$2:$T$21) -> 0 | Q12: =SUMPRODUCT((Config_Equipamentos!$B$2:$B$21="Irrigação/Lavoura")*(Config_Equipamentos!$C$2:$C$21="Bomba auxiliar")*Config_Equipamentos!$D$2:$D$21*Config_Equipamentos!$F$2:$F$21*Config_Equipamentos!$U$2:$U$21) -> 17.6 | R12: =SUMPRODUCT((Config_Equipamentos!$B$2:$B$21="Irrigação/Lavoura")*(Config_Equipamentos!$C$2:$C$21="Bomba auxiliar")*Config_Equipamentos!$D$2:$D$21*Config_Equipamentos!$F$2:$F$21*Config_Equipamentos!$V$2:$V$21) -> 17.6 | S12: =SUMPRODUCT((Config_Equipamentos!$B$2:$B$21="Irrigação/Lavoura")*(Config_Equipamentos!$C$2:$C$21="Bomba auxiliar")*Config_Equipamentos!$D$2:$D$21*Config_Equipamentos!$F$2:$F$21*Config_Equipamentos!$W$2:$W$21) -> 0 | T12: =SUMPRODUCT((Config_Equipamentos!$B$2:$B$21="Irrigação/Lavoura")*(Config_Equipamentos!$C$2:$C$21="Bomba auxiliar")*Config_Equipamentos!$D$2:$D$21*Config_Equipamentos!$F$2:$F$21*Config_Equipamentos!$X$2:$X$21) -> 0 | U12: =SUMPRODUCT((Config_Equipamentos!$B$2:$B$21="Irrigação/Lavoura")*(Config_Equipamentos!$C$2:$C$21="Bomba auxiliar")*Config_Equipamentos!$D$2:$D$21*Config_Equipamentos!$F$2:$F$21*Config_Equipamentos!$Y$2:$Y$21) -> 0 | V12: =SUMPRODUCT((Config_Equipamentos!$B$2:$B$21="Irrigação/Lavoura")*(Config_Equipamentos!$C$2:$C$21="Bomba auxiliar")*Config_Equipamentos!$D$2:$D$21*Config_Equipamentos!$F$2:$F$21*Config_Equipamentos!$Z$2:$Z$21) -> 0 | W12: =SUMPRODUCT((Config_Equipamentos!$B$2:$B$21="Irrigação/Lavoura")*(Config_Equipamentos!$C$2:$C$21="Bomba auxiliar")*Config_Equipamentos!$D$2:$D$21*Config_Equipamentos!$F$2:$F$21*Config_Equipamentos!$AA$2:$AA$21) -> 17.6 | X12: =SUMPRODUCT((Config_Equipamentos!$B$2:$B$21="Irrigação/Lavoura")*(Config_Equipamentos!$C$2:$C$21="Bomba auxiliar")*Config_Equipamentos!$D$2:$D$21*Config_Equipamentos!$F$2:$F$21*Config_Equipamentos!$AB$2:$AB$21) -> 17.6 | Y12: =SUMPRODUCT((Config_Equipamentos!$B$2:$B$21="Irrigação/Lavoura")*(Config_Equipamentos!$C$2:$C$21="Bomba auxiliar")*Config_Equipamentos!$D$2:$D$21*Config_Equipamentos!$F$2:$F$21*Config_Equipamentos!$AC$2:$AC$21) -> 0 | Z12: =SUMPRODUCT((Config_Equipamentos!$B$2:$B$21="Irrigação/Lavoura")*(Config_Equipamentos!$C$2:$C$21="Bomba auxiliar")*Config_Equipamentos!$D$2:$D$21*Config_Equipamentos!$F$2:$F$21*Config_Equipamentos!$AD$2:$AD$21) -> 0 | AA12: =SUM(C12:Z12) -> 140.8
A13: Secadora | B13: Pequena | C13: =SUMPRODUCT((Config_Equipamentos!$B$2:$B$21="Irrigação/Lavoura")*(Config_Equipamentos!$C$2:$C$21="Secadora/Silo")*Config_Equipamentos!$D$2:$D$21*Config_Equipamentos!$E$2:$E$21*Config_Equipamentos!$G$2:$G$21) -> 0 | D13: =SUMPRODUCT((Config_Equipamentos!$B$2:$B$21="Irrigação/Lavoura")*(Config_Equipamentos!$C$2:$C$21="Secadora/Silo")*Config_Equipamentos!$D$2:$D$21*Config_Equipamentos!$E$2:$E$21*Config_Equipamentos!$H$2:$H$21) -> 0 | E13: =SUMPRODUCT((Config_Equipamentos!$B$2:$B$21="Irrigação/Lavoura")*(Config_Equipamentos!$C$2:$C$21="Secadora/Silo")*Config_Equipamentos!$D$2:$D$21*Config_Equipamentos!$E$2:$E$21*Config_Equipamentos!$I$2:$I$21) -> 0 | F13: =SUMPRODUCT((Config_Equipamentos!$B$2:$B$21="Irrigação/Lavoura")*(Config_Equipamentos!$C$2:$C$21="Secadora/Silo")*Config_Equipamentos!$D$2:$D$21*Config_Equipamentos!$E$2:$E$21*Config_Equipamentos!$J$2:$J$21) -> 0 | G13: =SUMPRODUCT((Config_Equipamentos!$B$2:$B$21="Irrigação/Lavoura")*(Config_Equipamentos!$C$2:$C$21="Secadora/Silo")*Config_Equipamentos!$D$2:$D$21*Config_Equipamentos!$E$2:$E$21*Config_Equipamentos!$K$2:$K$21) -> 0 | H13: =SUMPRODUCT((Config_Equipamentos!$B$2:$B$21="Irrigação/Lavoura")*(Config_Equipamentos!$C$2:$C$21="Secadora/Silo")*Config_Equipamentos!$D$2:$D$21*Config_Equipamentos!$E$2:$E$21*Config_Equipamentos!$L$2:$L$21) -> 0 | I13: =SUMPRODUCT((Config_Equipamentos!$B$2:$B$21="Irrigação/Lavoura")*(Config_Equipamentos!$C$2:$C$21="Secadora/Silo")*Config_Equipamentos!$D$2:$D$21*Config_Equipamentos!$E$2:$E$21*Config_Equipamentos!$M$2:$M$21) -> 0 | J13: =SUMPRODUCT((Config_Equipamentos!$B$2:$B$21="Irrigação/Lavoura")*(Config_Equipamentos!$C$2:$C$21="Secadora/Silo")*Config_Equipamentos!$D$2:$D$21*Config_Equipamentos!$E$2:$E$21*Config_Equipamentos!$N$2:$N$21) -> 0 | K13: =SUMPRODUCT((Config_Equipamentos!$B$2:$B$21="Irrigação/Lavoura")*(Config_Equipamentos!$C$2:$C$21="Secadora/Silo")*Config_Equipamentos!$D$2:$D$21*Config_Equipamentos!$E$2:$E$21*Config_Equipamentos!$O$2:$O$21) -> 0 | L13: =SUMPRODUCT((Config_Equipamentos!$B$2:$B$21="Irrigação/Lavoura")*(Config_Equipamentos!$C$2:$C$21="Secadora/Silo")*Config_Equipamentos!$D$2:$D$21*Config_Equipamentos!$E$2:$E$21*Config_Equipamentos!$P$2:$P$21) -> 0 | M13: =SUMPRODUCT((Config_Equipamentos!$B$2:$B$21="Irrigação/Lavoura")*(Config_Equipamentos!$C$2:$C$21="Secadora/Silo")*Config_Equipamentos!$D$2:$D$21*Config_Equipamentos!$E$2:$E$21*Config_Equipamentos!$Q$2:$Q$21) -> 0 | N13: =SUMPRODUCT((Config_Equipamentos!$B$2:$B$21="Irrigação/Lavoura")*(Config_Equipamentos!$C$2:$C$21="Secadora/Silo")*Config_Equipamentos!$D$2:$D$21*Config_Equipamentos!$E$2:$E$21*Config_Equipamentos!$R$2:$R$21) -> 0 | O13: =SUMPRODUCT((Config_Equipamentos!$B$2:$B$21="Irrigação/Lavoura")*(Config_Equipamentos!$C$2:$C$21="Secadora/Silo")*Config_Equipamentos!$D$2:$D$21*Config_Equipamentos!$E$2:$E$21*Config_Equipamentos!$S$2:$S$21) -> 0 | P13: =SUMPRODUCT((Config_Equipamentos!$B$2:$B$21="Irrigação/Lavoura")*(Config_Equipamentos!$C$2:$C$21="Secadora/Silo")*Config_Equipamentos!$D$2:$D$21*Config_Equipamentos!$E$2:$E$21*Config_Equipamentos!$T$2:$T$21) -> 0 | Q13: =SUMPRODUCT((Config_Equipamentos!$B$2:$B$21="Irrigação/Lavoura")*(Config_Equipamentos!$C$2:$C$21="Secadora/Silo")*Config_Equipamentos!$D$2:$D$21*Config_Equipamentos!$E$2:$E$21*Config_Equipamentos!$U$2:$U$21) -> 0 | R13: =SUMPRODUCT((Config_Equipamentos!$B$2:$B$21="Irrigação/Lavoura")*(Config_Equipamentos!$C$2:$C$21="Secadora/Silo")*Config_Equipamentos!$D$2:$D$21*Config_Equipamentos!$E$2:$E$21*Config_Equipamentos!$V$2:$V$21) -> 0 | S13: =SUMPRODUCT((Config_Equipamentos!$B$2:$B$21="Irrigação/Lavoura")*(Config_Equipamentos!$C$2:$C$21="Secadora/Silo")*Config_Equipamentos!$D$2:$D$21*Config_Equipamentos!$E$2:$E$21*Config_Equipamentos!$W$2:$W$21) -> 0 | T13: =SUMPRODUCT((Config_Equipamentos!$B$2:$B$21="Irrigação/Lavoura")*(Config_Equipamentos!$C$2:$C$21="Secadora/Silo")*Config_Equipamentos!$D$2:$D$21*Config_Equipamentos!$E$2:$E$21*Config_Equipamentos!$X$2:$X$21) -> 0 | U13: =SUMPRODUCT((Config_Equipamentos!$B$2:$B$21="Irrigação/Lavoura")*(Config_Equipamentos!$C$2:$C$21="Secadora/Silo")*Config_Equipamentos!$D$2:$D$21*Config_Equipamentos!$E$2:$E$21*Config_Equipamentos!$Y$2:$Y$21) -> 0 | V13: =SUMPRODUCT((Config_Equipamentos!$B$2:$B$21="Irrigação/Lavoura")*(Config_Equipamentos!$C$2:$C$21="Secadora/Silo")*Config_Equipamentos!$D$2:$D$21*Config_Equipamentos!$E$2:$E$21*Config_Equipamentos!$Z$2:$Z$21) -> 0 | W13: =SUMPRODUCT((Config_Equipamentos!$B$2:$B$21="Irrigação/Lavoura")*(Config_Equipamentos!$C$2:$C$21="Secadora/Silo")*Config_Equipamentos!$D$2:$D$21*Config_Equipamentos!$E$2:$E$21*Config_Equipamentos!$AA$2:$AA$21) -> 0 | X13: =SUMPRODUCT((Config_Equipamentos!$B$2:$B$21="Irrigação/Lavoura")*(Config_Equipamentos!$C$2:$C$21="Secadora/Silo")*Config_Equipamentos!$D$2:$D$21*Config_Equipamentos!$E$2:$E$21*Config_Equipamentos!$AB$2:$AB$21) -> 0 | Y13: =SUMPRODUCT((Config_Equipamentos!$B$2:$B$21="Irrigação/Lavoura")*(Config_Equipamentos!$C$2:$C$21="Secadora/Silo")*Config_Equipamentos!$D$2:$D$21*Config_Equipamentos!$E$2:$E$21*Config_Equipamentos!$AC$2:$AC$21) -> 0 | Z13: =SUMPRODUCT((Config_Equipamentos!$B$2:$B$21="Irrigação/Lavoura")*(Config_Equipamentos!$C$2:$C$21="Secadora/Silo")*Config_Equipamentos!$D$2:$D$21*Config_Equipamentos!$E$2:$E$21*Config_Equipamentos!$AD$2:$AD$21) -> 0 | AA13: =SUM(C13:Z13) -> 0
